Workbook

Sheet Doctor review
A1: EMS review — start here
A2: 10 fictional reports created with AI. Not real patient recordings.
A3: Read each case. Fill only the yellow boxes. No diagnosis or treatment plan needed.
A4: Start with Cases 1–3, then discuss the questions and preparation choices with us before continuing.
A5: Reviews marked Done | B5: =COUNTIF(B14,"Done")+COUNTIF(B23,"Done")+COUNTIF(B32,"Done")+COUNTIF(B41,"Done")+COUNTIF(B50,"Done")+COUNTIF(B59,"Done")+COUNTIF(B68,"Done")+COUNTIF(B77,"Done")+COUNTIF(B86,"Done")+COUNTIF(B95,"Done")&" / 10" -> 0 / 10
A7: Case 1 · SYN001 · ETA 12 minutes
A8: Earlier report | B8: No earlier report provided.
A9: Current report | B9: Adult with shortness of breath. Speaking in full sentences. Heart rate 96, BP 136 over 82, respiratory rate 22, oxygen saturation 95 percent on room air. Symptoms began about an hour ago. No chest pain reported. No medication given during this transport. ETA twelve minutes.
A10: 1. Brief ED handoff 2–3 sentences
A11: 2. Important change?
A12: Why? What is missing? One sentence is enough
A13: 3. Preparation needed?
A14: Review status | B14: Not started
A16: Case 2 · SYN002 · ETA 20 minutes
A17: Earlier report | B17: Eight minutes earlier: heart rate 104, BP 118/76, respiratory rate 24, oxygen saturation 94 percent on room air. Awake and speaking normally.
A18: Current report | B18: Update on our adult with breathing trouble. Now only speaking a few words at a time. Heart rate 126, BP 100 over 64, respirations thirty, saturation 89 percent on room air. We have started oxygen, but do not have a repeat saturation yet. Twenty minutes out.
A19: 1. Brief ED handoff 2–3 sentences
A20: 2. Important change?
A21: Why? What is missing? One sentence is enough
A22: 3. Preparation needed?
A23: Review status | B23: Not started
A25: Case 3 · SYN003 · ETA 9 minutes
A26: Earlier report | B26: Six minutes earlier: awake, heart rate 112, BP 124/80. Reported chest discomfort.
A27: Current report | B27: Chest discomfort is still present. Patient says it is about the same. Heart rate 110 and BP 122 over 78. No fainting reported. Aspirin was given before this update; the dose was not stated in our report. Nine minutes out. We have not transmitted an ECG interpretation.
A28: 1. Brief ED handoff 2–3 sentences
A29: 2. Important change?
A30: Why? What is missing? One sentence is enough
A31: 3. Preparation needed?
A32: Review status | B32: Not started
A34: Case 4 · SYN004 · ETA 25 minutes
A35: Earlier report | B35: No earlier report provided.
A36: Current report | B36: Adult with new trouble speaking and right arm weakness. Family says last seen normal around forty minutes before this call, but that time is approximate. Glucose 108 milligrams per deciliter. Awake. BP 172 over 96, pulse 88. We cannot confirm anticoagulant use. Twenty-five minutes to your facility.
A37: 1. Brief ED handoff 2–3 sentences
A38: 2. Important change?
A39: Why? What is missing? One sentence is enough
A40: 3. Preparation needed?
A41: Review status | B41: Not started
A43: Case 5 · SYN005 · ETA 18 minutes
A44: Earlier report | B44: Ten minutes earlier: awake and following commands, heart rate 108. Crew described BP as low but did not give a number.
A45: Current report | B45: Patient is now difficult to keep awake and answers only after repeated prompting. Pulse 124. Blood pressure was low earlier, but we do not have a repeat measurement. There is no documented oxygen saturation in this update. Eighteen minutes out.
...

Sheet Queue exercise
A1: Queue exercise — optional after Cases 1–3
A2: Within each group: 1 = prepare first. Ties are allowed. Choose Unsure if you cannot judge.
A3: Use the reports, ETAs and stated resources. Do not assume extra resources.
A4: These are separate simulated ED snapshots; no in-hospital patients are included.
A6: Group 1 · One preparation bay and one available preparation team.
A7: SYN001 · ETA 12 minutes
A8: Earlier report | B8: No earlier report provided.
A9: Current report | B9: Adult with shortness of breath. Speaking in full sentences. Heart rate 96, BP 136 over 82, respiratory rate 22, oxygen saturation 95 percent on room air. Symptoms began about an hour ago. No chest pain reported. No medication given during this transport. ETA twelve minutes.
A10: Preparation order
A11: SYN004 · ETA 25 minutes
A12: Earlier report | B12: No earlier report provided.
A13: Current report | B13: Adult with new trouble speaking and right arm weakness. Family says last seen normal around forty minutes before this call, but that time is approximate. Glucose 108 milligrams per deciliter. Awake. BP 172 over 96, pulse 88. We cannot confirm anticoagulant use. Twenty-five minutes to your facility.
A14: Preparation order
A15: SYN007 · ETA 15 minutes
A16: Earlier report | B16: No earlier report provided.
A17: Current report | B17: Adult after a fall. Reports left ankle pain, no reported head strike or loss of consciousness. Awake and speaking normally. Heart rate 84, BP 128 over 74, oxygen saturation 98 percent on room air. No other injury identified in our report. Fifteen minutes out.
A18: Preparation order
A19: Why this order? A short explanation is enough
A20: Review status | B20: Not started
A22: Group 2 · Two preparation bays and one available preparation team.
A23: SYN002 · ETA 20 minutes
A24: Earlier report | B24: Eight minutes earlier: heart rate 104, BP 118/76, respiratory rate 24, oxygen saturation 94 percent on room air. Awake and speaking normally.
A25: Current report | B25: Update on our adult with breathing trouble. Now only speaking a few words at a time. Heart rate 126, BP 100 over 64, respirations thirty, saturation 89 percent on room air. We have started oxygen, but do not have a repeat saturation yet. Twenty minutes out.
A26: Preparation order
A27: SYN008 · ETA 30 minutes
A28: Earlier report | B28: Seven minutes earlier: heart rate 118, BP 110/70, respiratory rate 24. Awake, reported fever and weakness.
A29: Current report | B29: Still weak. Heart rate 128, BP 92 over 58, respirations 28. Temperature thirty-nine point one degrees Celsius. Still answering questions, but slower than before. IV access obtained. Fluids are planned but have not yet been started. Thirty minutes out.
A30: Preparation order
A31: SYN010 · ETA 11 minutes
A32: Earlier report | B32: Nine minutes earlier: after a vehicle collision, awake, heart rate 106, BP 126/84. Reported abdominal pain.
A33: Current report | B33: Abdominal pain is worse. Pulse 132, BP 90 over 60. Patient now appears pale and says they feel faint. External bleeding is not seen. We have not assessed internal bleeding. Eleven minutes out.
A34: Preparation order
A35: Why this order? A short explanation is enough
A36: Review status | B36: Not started

Sheet Progress
A2: EMS clinician annotation
A4: Pilot review progress | B4: Count | D4: Start with the pilot
A5: Cases with review rows | B5: =COUNTA('Clinical review'!A2:A61) -> 10
A6: Not started | B6: =COUNTIFS('Clinical review'!A2:A61,"<>",'Clinical review'!C2:C61,"Not started") -> 10 | D6: 1. Read the accompanying guide.
A7: In progress | B7: =COUNTIFS('Clinical review'!A2:A61,"<>",'Clinical review'!C2:C61,"In progress") -> 0 | D7: 2. Review Cases, then Observations.
A8: Needs clarification | B8: =COUNTIFS('Clinical review'!A2:A61,"<>",'Clinical review'!C2:C61,"Needs clarification") -> 0 | D8: 3. Complete Clinical review.
A9: Marked completed | B9: =COUNTIFS('Clinical review'!A2:A61,"<>",'Clinical review'!C2:C61,"Completed") -> 0 | D9: 4. Rank Queue review separately.
A10: Finalized clinician reviews | B10: =COUNTIFS('Clinical review'!T2:T61,"Yes") -> 0 | D10: 5. Resolve questions and approve the rubric.
A11: Completion proportion | B11: =IF(B5=0,"n.a.",B10/B5) -> 0 | D11: All 10 cases are synthetic and unreviewed.
A12: Completed but not finalized | B12: =B9-B10 -> 0 | D12: No source audio has been supplied.
A13: Reported review time (minutes) | B13: =SUM('Clinical review'!R2:R61) -> 0 | D13: Finalized means complete under the approved rubric.
A16: Rubric approval | B16: Clinician to complete
A17: Rubric version | B17: draft_v0.1
A18: Approval status | B18: Not approved
A20: Queue review | B20: Patient judgments
A21: Assigned queue rows | B21: =COUNTA('Queue review'!A2:A31) -> 6
A22: Marked completed | B22: =COUNTIFS('Queue review'!A2:A31,"<>",'Queue review'!I2:I31,"Completed") -> 0

Sheet Clinical review
A1: case_id | B1: encounter_id | C1: status | D1: reviewer_id | E1: reviewed_at_UTC | F1: rubric_version | G1: attention_category | H1: meaningful_change | I1: change_evidence | J1: missing_information | K1: essential_facts | L1: unsupported_inferences_to_avoid | M1: reference_summary | N1: observations_reviewed | O1: summary_reviewed | P1: clinical_reviewed | Q1: open_questions | R1: review_minutes | S1: completion_check | T1: finalized
A2: SYN001 | B2: E001 | C2: Not started | S2: =IF(A2="","",IF(AND(D2<>"",E2<>"",F2<>"",G2<>"",H2<>"",I2<>"",J2<>"",K2<>"",L2<>"",M2<>"",N2="Yes",O2="Yes",P2="Yes",OR(Q2="",Q2="None")),"Ready","Incomplete")) -> Incomplete | T2: =IF(A2="","",IF(AND(C2="Completed",S2="Ready",Progress!B18="Approved",F2=Progress!B17),"Yes","No")) -> No
A3: SYN002 | B3: E002 | C3: Not started | S3: =IF(A3="","",IF(AND(D3<>"",E3<>"",F3<>"",G3<>"",H3<>"",I3<>"",J3<>"",K3<>"",L3<>"",M3<>"",N3="Yes",O3="Yes",P3="Yes",OR(Q3="",Q3="None")),"Ready","Incomplete")) -> Incomplete | T3: =IF(A3="","",IF(AND(C3="Completed",S3="Ready",Progress!B18="Approved",F3=Progress!B17),"Yes","No")) -> No
A4: SYN003 | B4: E003 | C4: Not started | S4: =IF(A4="","",IF(AND(D4<>"",E4<>"",F4<>"",G4<>"",H4<>"",I4<>"",J4<>"",K4<>"",L4<>"",M4<>"",N4="Yes",O4="Yes",P4="Yes",OR(Q4="",Q4="None")),"Ready","Incomplete")) -> Incomplete | T4: =IF(A4="","",IF(AND(C4="Completed",S4="Ready",Progress!B18="Approved",F4=Progress!B17),"Yes","No")) -> No
A5: SYN004 | B5: E004 | C5: Not started | S5: =IF(A5="","",IF(AND(D5<>"",E5<>"",F5<>"",G5<>"",H5<>"",I5<>"",J5<>"",K5<>"",L5<>"",M5<>"",N5="Yes",O5="Yes",P5="Yes",OR(Q5="",Q5="None")),"Ready","Incomplete")) -> Incomplete | T5: =IF(A5="","",IF(AND(C5="Completed",S5="Ready",Progress!B18="Approved",F5=Progress!B17),"Yes","No")) -> No
A6: SYN005 | B6: E005 | C6: Not started | S6: =IF(A6="","",IF(AND(D6<>"",E6<>"",F6<>"",G6<>"",H6<>"",I6<>"",J6<>"",K6<>"",L6<>"",M6<>"",N6="Yes",O6="Yes",P6="Yes",OR(Q6="",Q6="None")),"Ready","Incomplete")) -> Incomplete | T6: =IF(A6="","",IF(AND(C6="Completed",S6="Ready",Progress!B18="Approved",F6=Progress!B17),"Yes","No")) -> No
A7: SYN006 | B7: E006 | C7: Not started | S7: =IF(A7="","",IF(AND(D7<>"",E7<>"",F7<>"",G7<>"",H7<>"",I7<>"",J7<>"",K7<>"",L7<>"",M7<>"",N7="Yes",O7="Yes",P7="Yes",OR(Q7="",Q7="None")),"Ready","Incomplete")) -> Incomplete | T7: =IF(A7="","",IF(AND(C7="Completed",S7="Ready",Progress!B18="Approved",F7=Progress!B17),"Yes","No")) -> No
A8: SYN007 | B8: E007 | C8: Not started | S8: =IF(A8="","",IF(AND(D8<>"",E8<>"",F8<>"",G8<>"",H8<>"",I8<>"",J8<>"",K8<>"",L8<>"",M8<>"",N8="Yes",O8="Yes",P8="Yes",OR(Q8="",Q8="None")),"Ready","Incomplete")) -> Incomplete | T8: =IF(A8="","",IF(AND(C8="Completed",S8="Ready",Progress!B18="Approved",F8=Progress!B17),"Yes","No")) -> No
A9: SYN008 | B9: E008 | C9: Not started | S9: =IF(A9="","",IF(AND(D9<>"",E9<>"",F9<>"",G9<>"",H9<>"",I9<>"",J9<>"",K9<>"",L9<>"",M9<>"",N9="Yes",O9="Yes",P9="Yes",OR(Q9="",Q9="None")),"Ready","Incomplete")) -> Incomplete | T9: =IF(A9="","",IF(AND(C9="Completed",S9="Ready",Progress!B18="Approved",F9=Progress!B17),"Yes","No")) -> No
A10: SYN009 | B10: E009 | C10: Not started | S10: =IF(A10="","",IF(AND(D10<>"",E10<>"",F10<>"",G10<>"",H10<>"",I10<>"",J10<>"",K10<>"",L10<>"",M10<>"",N10="Yes",O10="Yes",P10="Yes",OR(Q10="",Q10="None")),"Ready","Incomplete")) -> Incomplete | T10: =IF(A10="","",IF(AND(C10="Completed",S10="Ready",Progress!B18="Approved",F10=Progress!B17),"Yes","No")) -> No
A11: SYN010 | B11: E010 | C11: Not started | S11: =IF(A11="","",IF(AND(D11<>"",E11<>"",F11<>"",G11<>"",H11<>"",I11<>"",J11<>"",K11<>"",L11<>"",M11<>"",N11="Yes",O11="Yes",P11="Yes",OR(Q11="",Q11="None")),"Ready","Incomplete")) -> Incomplete | T11: =IF(A11="","",IF(AND(C11="Completed",S11="Ready",Progress!B18="Approved",F11=Progress!B17),"Yes","No")) -> No
S12: =IF(A12="","",IF(AND(D12<>"",E12<>"",F12<>"",G12<>"",H12<>"",I12<>"",J12<>"",K12<>"",L12<>"",M12<>"",N12="Yes",O12="Yes",P12="Yes",OR(Q12="",Q12="None")),"Ready","Incomplete")) | T12: =IF(A12="","",IF(AND(C12="Completed",S12="Ready",Progress!B18="Approved",F12=Progress!B17),"Yes","No"))
S13: =IF(A13="","",IF(AND(D13<>"",E13<>"",F13<>"",G13<>"",H13<>"",I13<>"",J13<>"",K13<>"",L13<>"",M13<>"",N13="Yes",O13="Yes",P13="Yes",OR(Q13="",Q13="None")),"Ready","Incomplete")) | T13: =IF(A13="","",IF(AND(C13="Completed",S13="Ready",Progress!B18="Approved",F13=Progress!B17),"Yes","No"))
S14: =IF(A14="","",IF(AND(D14<>"",E14<>"",F14<>"",G14<>"",H14<>"",I14<>"",J14<>"",K14<>"",L14<>"",M14<>"",N14="Yes",O14="Yes",P14="Yes",OR(Q14="",Q14="None")),"Ready","Incomplete")) | T14: =IF(A14="","",IF(AND(C14="Completed",S14="Ready",Progress!B18="Approved",F14=Progress!B17),"Yes","No"))
S15: =IF(A15="","",IF(AND(D15<>"",E15<>"",F15<>"",G15<>"",H15<>"",I15<>"",J15<>"",K15<>"",L15<>"",M15<>"",N15="Yes",O15="Yes",P15="Yes",OR(Q15="",Q15="None")),"Ready","Incomplete")) | T15: =IF(A15="","",IF(AND(C15="Completed",S15="Ready",Progress!B18="Approved",F15=Progress!B17),"Yes","No"))
S16: =IF(A16="","",IF(AND(D16<>"",E16<>"",F16<>"",G16<>"",H16<>"",I16<>"",J16<>"",K16<>"",L16<>"",M16<>"",N16="Yes",O16="Yes",P16="Yes",OR(Q16="",Q16="None")),"Ready","Incomplete")) | T16: =IF(A16="","",IF(AND(C16="Completed",S16="Ready",Progress!B18="Approved",F16=Progress!B17),"Yes","No"))
S17: =IF(A17="","",IF(AND(D17<>"",E17<>"",F17<>"",G17<>"",H17<>"",I17<>"",J17<>"",K17<>"",L17<>"",M17<>"",N17="Yes",O17="Yes",P17="Yes",OR(Q17="",Q17="None")),"Ready","Incomplete")) | T17: =IF(A17="","",IF(AND(C17="Completed",S17="Ready",Progress!B18="Approved",F17=Progress!B17),"Yes","No"))
S18: =IF(A18="","",IF(AND(D18<>"",E18<>"",F18<>"",G18<>"",H18<>"",I18<>"",J18<>"",K18<>"",L18<>"",M18<>"",N18="Yes",O18="Yes",P18="Yes",OR(Q18="",Q18="None")),"Ready","Incomplete")) | T18: =IF(A18="","",IF(AND(C18="Completed",S18="Ready",Progress!B18="Approved",F18=Progress!B17),"Yes","No"))
S19: =IF(A19="","",IF(AND(D19<>"",E19<>"",F19<>"",G19<>"",H19<>"",I19<>"",J19<>"",K19<>"",L19<>"",M19<>"",N19="Yes",O19="Yes",P19="Yes",OR(Q19="",Q19="None")),"Ready","Incomplete")) | T19: =IF(A19="","",IF(AND(C19="Completed",S19="Ready",Progress!B18="Approved",F19=Progress!B17),"Yes","No"))
S20: =IF(A20="","",IF(AND(D20<>"",E20<>"",F20<>"",G20<>"",H20<>"",I20<>"",J20<>"",K20<>"",L20<>"",M20<>"",N20="Yes",O20="Yes",P20="Yes",OR(Q20="",Q20="None")),"Ready","Incomplete")) | T20: =IF(A20="","",IF(AND(C20="Completed",S20="Ready",Progress!B18="Approved",F20=Progress!B17),"Yes","No"))
S21: =IF(A21="","",IF(AND(D21<>"",E21<>"",F21<>"",G21<>"",H21<>"",I21<>"",J21<>"",K21<>"",L21<>"",M21<>"",N21="Yes",O21="Yes",P21="Yes",OR(Q21="",Q21="None")),"Ready","Incomplete")) | T21: =IF(A21="","",IF(AND(C21="Completed",S21="Ready",Progress!B18="Approved",F21=Progress!B17),"Yes","No"))
S22: =IF(A22="","",IF(AND(D22<>"",E22<>"",F22<>"",G22<>"",H22<>"",I22<>"",J22<>"",K22<>"",L22<>"",M22<>"",N22="Yes",O22="Yes",P22="Yes",OR(Q22="",Q22="None")),"Ready","Incomplete")) | T22: =IF(A22="","",IF(AND(C22="Completed",S22="Ready",Progress!B18="Approved",F22=Progress!B17),"Yes","No"))
S23: =IF(A23="","",IF(AND(D23<>"",E23<>"",F23<>"",G23<>"",H23<>"",I23<>"",J23<>"",K23<>"",L23<>"",M23<>"",N23="Yes",O23="Yes",P23="Yes",OR(Q23="",Q23="None")),"Ready","Incomplete")) | T23: =IF(A23="","",IF(AND(C23="Completed",S23="Ready",Progress!B18="Approved",F23=Progress!B17),"Yes","No"))
S24: =IF(A24="","",IF(AND(D24<>"",E24<>"",F24<>"",G24<>"",H24<>"",I24<>"",J24<>"",K24<>"",L24<>"",M24<>"",N24="Yes",O24="Yes",P24="Yes",OR(Q24="",Q24="None")),"Ready","Incomplete")) | T24: =IF(A24="","",IF(AND(C24="Completed",S24="Ready",Progress!B18="Approved",F24=Progress!B17),"Yes","No"))
S25: =IF(A25="","",IF(AND(D25<>"",E25<>"",F25<>"",G25<>"",H25<>"",I25<>"",J25<>"",K25<>"",L25<>"",M25<>"",N25="Yes",O25="Yes",P25="Yes",OR(Q25="",Q25="None")),"Ready","Incomplete")) | T25: =IF(A25="","",IF(AND(C25="Completed",S25="Ready",Progress!B18="Approved",F25=Progress!B17),"Yes","No"))
S26: =IF(A26="","",IF(AND(D26<>"",E26<>"",F26<>"",G26<>"",H26<>"",I26<>"",J26<>"",K26<>"",L26<>"",M26<>"",N26="Yes",O26="Yes",P26="Yes",OR(Q26="",Q26="None")),"Ready","Incomplete")) | T26: =IF(A26="","",IF(AND(C26="Completed",S26="Ready",Progress!B18="Approved",F26=Progress!B17),"Yes","No"))
S27: =IF(A27="","",IF(AND(D27<>"",E27<>"",F27<>"",G27<>"",H27<>"",I27<>"",J27<>"",K27<>"",L27<>"",M27<>"",N27="Yes",O27="Yes",P27="Yes",OR(Q27="",Q27="None")),"Ready","Incomplete")) | T27: =IF(A27="","",IF(AND(C27="Completed",S27="Ready",Progress!B18="Approved",F27=Progress!B17),"Yes","No"))
S28: =IF(A28="","",IF(AND(D28<>"",E28<>"",F28<>"",G28<>"",H28<>"",I28<>"",J28<>"",K28<>"",L28<>"",M28<>"",N28="Yes",O28="Yes",P28="Yes",OR(Q28="",Q28="None")),"Ready","Incomplete")) | T28: =IF(A28="","",IF(AND(C28="Completed",S28="Ready",Progress!B18="Approved",F28=Progress!B17),"Yes","No"))
S29: =IF(A29="","",IF(AND(D29<>"",E29<>"",F29<>"",G29<>"",H29<>"",I29<>"",J29<>"",K29<>"",L29<>"",M29<>"",N29="Yes",O29="Yes",P29="Yes",OR(Q29="",Q29="None")),"Ready","Incomplete")) | T29: =IF(A29="","",IF(AND(C29="Completed",S29="Ready",Progress!B18="Approved",F29=Progress!B17),"Yes","No"))
S30: =IF(A30="","",IF(AND(D30<>"",E30<>"",F30<>"",G30<>"",H30<>"",I30<>"",J30<>"",K30<>"",L30<>"",M30<>"",N30="Yes",O30="Yes",P30="Yes",OR(Q30="",Q30="None")),"Ready","Incomplete")) | T30: =IF(A30="","",IF(AND(C30="Completed",S30="Ready",Progress!B18="Approved",F30=Progress!B17),"Yes","No"))
S31: =IF(A31="","",IF(AND(D31<>"",E31<>"",F31<>"",G31<>"",H31<>"",I31<>"",J31<>"",K31<>"",L31<>"",M31<>"",N31="Yes",O31="Yes",P31="Yes",OR(Q31="",Q31="None")),"Ready","Incomplete")) | T31: =IF(A31="","",IF(AND(C31="Completed",S31="Ready",Progress!B18="Approved",F31=Progress!B17),"Yes","No"))
S32: =IF(A32="","",IF(AND(D32<>"",E32<>"",F32<>"",G32<>"",H32<>"",I32<>"",J32<>"",K32<>"",L32<>"",M32<>"",N32="Yes",O32="Yes",P32="Yes",OR(Q32="",Q32="None")),"Ready","Incomplete")) | T32: =IF(A32="","",IF(AND(C32="Completed",S32="Ready",Progress!B18="Approved",F32=Progress!B17),"Yes","No"))
S33: =IF(A33="","",IF(AND(D33<>"",E33<>"",F33<>"",G33<>"",H33<>"",I33<>"",J33<>"",K33<>"",L33<>"",M33<>"",N33="Yes",O33="Yes",P33="Yes",OR(Q33="",Q33="None")),"Ready","Incomplete")) | T33: =IF(A33="","",IF(AND(C33="Completed",S33="Ready",Progress!B18="Approved",F33=Progress!B17),"Yes","No"))
S34: =IF(A34="","",IF(AND(D34<>"",E34<>"",F34<>"",G34<>"",H34<>"",I34<>"",J34<>"",K34<>"",L34<>"",M34<>"",N34="Yes",O34="Yes",P34="Yes",OR(Q34="",Q34="None")),"Ready","Incomplete")) | T34: =IF(A34="","",IF(AND(C34="Completed",S34="Ready",Progress!B18="Approved",F34=Progress!B17),"Yes","No"))
S35: =IF(A35="","",IF(AND(D35<>"",E35<>"",F35<>"",G35<>"",H35<>"",I35<>"",J35<>"",K35<>"",L35<>"",M35<>"",N35="Yes",O35="Yes",P35="Yes",OR(Q35="",Q35="None")),"Ready","Incomplete")) | T35: =IF(A35="","",IF(AND(C35="Completed",S35="Ready",Progress!B18="Approved",F35=Progress!B17),"Yes","No"))
S36: =IF(A36="","",IF(AND(D36<>"",E36<>"",F36<>"",G36<>"",H36<>"",I36<>"",J36<>"",K36<>"",L36<>"",M36<>"",N36="Yes",O36="Yes",P36="Yes",OR(Q36="",Q36="None")),"Ready","Incomplete")) | T36: =IF(A36="","",IF(AND(C36="Completed",S36="Ready",Progress!B18="Approved",F36=Progress!B17),"Yes","No"))
S37: =IF(A37="","",IF(AND(D37<>"",E37<>"",F37<>"",G37<>"",H37<>"",I37<>"",J37<>"",K37<>"",L37<>"",M37<>"",N37="Yes",O37="Yes",P37="Yes",OR(Q37="",Q37="None")),"Ready","Incomplete")) | T37: =IF(A37="","",IF(AND(C37="Completed",S37="Ready",Progress!B18="Approved",F37=Progress!B17),"Yes","No"))
S38: =IF(A38="","",IF(AND(D38<>"",E38<>"",F38<>"",G38<>"",H38<>"",I38<>"",J38<>"",K38<>"",L38<>"",M38<>"",N38="Yes",O38="Yes",P38="Yes",OR(Q38="",Q38="None")),"Ready","Incomplete")) | T38: =IF(A38="","",IF(AND(C38="Completed",S38="Ready",Progress!B18="Approved",F38=Progress!B17),"Yes","No"))
S39: =IF(A39="","",IF(AND(D39<>"",E39<>"",F39<>"",G39<>"",H39<>"",I39<>"",J39<>"",K39<>"",L39<>"",M39<>"",N39="Yes",O39="Yes",P39="Yes",OR(Q39="",Q39="None")),"Ready","Incomplete")) | T39: =IF(A39="","",IF(AND(C39="Completed",S39="Ready",Progress!B18="Approved",F39=Progress!B17),"Yes","No"))
S40: =IF(A40="","",IF(AND(D40<>"",E40<>"",F40<>"",G40<>"",H40<>"",I40<>"",J40<>"",K40<>"",L40<>"",M40<>"",N40="Yes",O40="Yes",P40="Yes",OR(Q40="",Q40="None")),"Ready","Incomplete")) | T40: =IF(A40="","",IF(AND(C40="Completed",S40="Ready",Progress!B18="Approved",F40=Progress!B17),"Yes","No"))
...

Sheet Observations
A1: case_id | B1: field_name | C1: assertion_status | D1: numeric_value | E1: reported_text | F1: unit | G1: time_reference | H1: source_report | I1: supporting_quote | J1: reviewer_id | K1: rubric_version | L1: annotation_notes
A2: SYN001 | B2: chief_complaint
A3: SYN001 | B3: heart_rate
A4: SYN001 | B4: blood_pressure_systolic
A5: SYN001 | B5: blood_pressure_diastolic
A6: SYN001 | B6: respiratory_rate
A7: SYN001 | B7: oxygen_saturation
A8: SYN001 | B8: mental_status
A9: SYN001 | B9: interventions
A10: SYN001 | B10: eta
A11: SYN002 | B11: chief_complaint
A12: SYN002 | B12: heart_rate
A13: SYN002 | B13: blood_pressure_systolic
... A91: SYN010 | B91: eta

Sheet Queue review
A1: queue_id | B1: case_id | C1: eta_minutes | D1: resource_context | E1: prior_information | F1: current_transcript | G1: priority_tier | H1: ordering_confidence | I1: status | J1: reviewer_id | K1: rubric_version | L1: ordering_rationale | M1: evidence_quote | N1: reviewed_at_UTC | O1: open_questions
A2: Q01 | B2: SYN001 | C2: 12 | D2: Synthetic ED A: one preparation bay and one available preparation team. No competing in-hospital demand is represented. | E2: No earlier report provided. | F2: Adult with shortness of breath. Speaking in full sentences. Heart rate 96, BP 136 over 82, respiratory rate 22, oxygen saturation 95 percent on room air. Symptoms began about an hour ago. No chest pain reported. No medication given during this transport. ETA twelve minutes. | I2: Not started
A3: Q01 | B3: SYN004 | C3: 25 | D3: Synthetic ED A: one preparation bay and one available preparation team. No competing in-hospital demand is represented. | E3: No earlier report provided. | F3: Adult with new trouble speaking and right arm weakness. Family says last seen normal around forty minutes before this call, but that time is approximate. Glucose 108 milligrams per deciliter. Awake. BP 172 over 96, pulse 88. We cannot confirm anticoagulant use. Twenty-five minutes to your facility. | I3: Not started
A4: Q01 | B4: SYN007 | C4: 15 | D4: Synthetic ED A: one preparation bay and one available preparation team. No competing in-hospital demand is represented. | E4: No earlier report provided. | F4: Adult after a fall. Reports left ankle pain, no reported head strike or loss of consciousness. Awake and speaking normally. Heart rate 84, BP 128 over 74, oxygen saturation 98 percent on room air. No other injury identified in our report. Fifteen minutes out. | I4: Not started
A5: Q02 | B5: SYN002 | C5: 20 | D5: Synthetic ED B: two preparation bays and one available preparation team. No competing in-hospital demand is represented. | E5: Eight minutes earlier: heart rate 104, BP 118/76, respiratory rate 24, oxygen saturation 94 percent on room air. Awake and speaking normally. | F5: Update on our adult with breathing trouble. Now only speaking a few words at a time. Heart rate 126, BP 100 over 64, respirations thirty, saturation 89 percent on room air. We have started oxygen, but do not have a repeat saturation yet. Twenty minutes out. | I5: Not started
A6: Q02 | B6: SYN008 | C6: 30 | D6: Synthetic ED B: two preparation bays and one available preparation team. No competing in-hospital demand is represented. | E6: Seven minutes earlier: heart rate 118, BP 110/70, respiratory rate 24. Awake, reported fever and weakness. | F6: Still weak. Heart rate 128, BP 92 over 58, respirations 28. Temperature thirty-nine point one degrees Celsius. Still answering questions, but slower than before. IV access obtained. Fluids are planned but have not yet been started. Thirty minutes out. | I6: Not started
A7: Q02 | B7: SYN010 | C7: 11 | D7: Synthetic ED B: two preparation bays and one available preparation team. No competing in-hospital demand is represented. | E7: Nine minutes earlier: after a vehicle collision, awake, heart rate 106, BP 126/84. Reported abdominal pain. | F7: Abdominal pain is worse. Pulse 132, BP 90 over 60. Patient now appears pale and says they feel faint. External bleeding is not seen. We have not assessed internal bleeding. Eleven minutes out. | I7: Not started

Sheet Cases
A1: case_id | B1: encounter_id | C1: update_number | D1: elapsed_minutes | E1: eta_minutes | F1: prior_information | G1: current_transcript | H1: source_type | I1: audio_available | J1: dataset_split | K1: source_version
A2: SYN001 | B2: E001 | C2: 1 | D2: 0 | E2: 12 | F2: No earlier report provided. | G2: Adult with shortness of breath. Speaking in full sentences. Heart rate 96, BP 136 over 82, respiratory rate 22, oxygen saturation 95 percent on room air. Symptoms began about an hour ago. No chest pain reported. No medication given during this transport. ETA twelve minutes. | H2: Synthetic authored fixture | I2: No | J2: Pilot only | K2: pilot_v1
A3: SYN002 | B3: E002 | C3: 2 | D3: 8 | E3: 20 | F3: Eight minutes earlier: heart rate 104, BP 118/76, respiratory rate 24, oxygen saturation 94 percent on room air. Awake and speaking normally. | G3: Update on our adult with breathing trouble. Now only speaking a few words at a time. Heart rate 126, BP 100 over 64, respirations thirty, saturation 89 percent on room air. We have started oxygen, but do not have a repeat saturation yet. Twenty minutes out. | H3: Synthetic authored fixture | I3: No | J3: Pilot only | K3: pilot_v1
A4: SYN003 | B4: E003 | C4: 2 | D4: 6 | E4: 9 | F4: Six minutes earlier: awake, heart rate 112, BP 124/80. Reported chest discomfort. | G4: Chest discomfort is still present. Patient says it is about the same. Heart rate 110 and BP 122 over 78. No fainting reported. Aspirin was given before this update; the dose was not stated in our report. Nine minutes out. We have not transmitted an ECG interpretation. | H4: Synthetic authored fixture | I4: No | J4: Pilot only | K4: pilot_v1
A5: SYN004 | B5: E004 | C5: 1 | D5: 0 | E5: 25 | F5: No earlier report provided. | G5: Adult with new trouble speaking and right arm weakness. Family says last seen normal around forty minutes before this call, but that time is approximate. Glucose 108 milligrams per deciliter. Awake. BP 172 over 96, pulse 88. We cannot confirm anticoagulant use. Twenty-five minutes to your facility. | H5: Synthetic authored fixture | I5: No | J5: Pilot only | K5: pilot_v1
A6: SYN005 | B6: E005 | C6: 2 | D6: 10 | E6: 18 | F6: Ten minutes earlier: awake and following commands, heart rate 108. Crew described BP as low but did not give a number. | G6: Patient is now difficult to keep awake and answers only after repeated prompting. Pulse 124. Blood pressure was low earlier, but we do not have a repeat measurement. There is no documented oxygen saturation in this update. Eighteen minutes out. | H6: Synthetic authored fixture | I6: No | J6: Pilot only | K6: pilot_v1
A7: SYN006 | B7: E006 | C7: 2 | D7: 5 | E7: 6 | F7: Five minutes earlier: glucose 48 mg/dL, confused, heart rate 102. | G7: After glucose treatment, repeat glucose is 92 milligrams per deciliter. Now awake and answering questions appropriately. Heart rate 94. Treatment dose and route were not included in the radio report. Six minutes out. | H7: Synthetic authored fixture | I7: No | J7: Pilot only | K7: pilot_v1
A8: SYN007 | B8: E007 | C8: 1 | D8: 0 | E8: 15 | F8: No earlier report provided. | G8: Adult after a fall. Reports left ankle pain, no reported head strike or loss of consciousness. Awake and speaking normally. Heart rate 84, BP 128 over 74, oxygen saturation 98 percent on room air. No other injury identified in our report. Fifteen minutes out. | H8: Synthetic authored fixture | I8: No | J8: Pilot only | K8: pilot_v1
A9: SYN008 | B9: E008 | C9: 2 | D9: 7 | E9: 30 | F9: Seven minutes earlier: heart rate 118, BP 110/70, respiratory rate 24. Awake, reported fever and weakness. | G9: Still weak. Heart rate 128, BP 92 over 58, respirations 28. Temperature thirty-nine point one degrees Celsius. Still answering questions, but slower than before. IV access obtained. Fluids are planned but have not yet been started. Thirty minutes out. | H9: Synthetic authored fixture | I9: No | J9: Pilot only | K9: pilot_v1
A10: SYN009 | B10: E009 | C10: 2 | D10: 4 | E10: 14 | F10: Four minutes earlier: heart rate 100, BP 120/80. Awake. Oxygen saturation not reported. | G10: Monitor showed saturation 82 percent, then 96 percent after we repositioned the probe. Patient is speaking normally. We cannot tell whether the first reading was accurate. Pulse 98, BP 118 over 78. No oxygen treatment reported. Fourteen minutes out. | H10: Synthetic authored fixture | I10: No | J10: Pilot only | K10: pilot_v1
A11: SYN010 | B11: E010 | C11: 2 | D11: 9 | E11: 11 | F11: Nine minutes earlier: after a vehicle collision, awake, heart rate 106, BP 126/84. Reported abdominal pain. | G11: Abdominal pain is worse. Pulse 132, BP 90 over 60. Patient now appears pale and says they feel faint. External bleeding is not seen. We have not assessed internal bleeding. Eleven minutes out. | H11: Synthetic authored fixture | I11: No | J11: Pilot only | K11: pilot_v1

Sheet Codebook
A1: Field or workflow | B1: Definition
A2: Dataset | B2: 10 synthetic, independent encounters. Text was authored for annotation-workflow testing. No real EMT audio, clinician labels, or patient outcomes are supplied.
A3: Input colors | B3: Pale amber cells are clinician inputs. Gray cells are calculated. Source transcripts must not be edited.
A4: Case selection | B4: Each case contains only its current report and the supplied earlier report. Do not infer subsequent outcomes.
A5: Assertion status | B5: Reported = explicitly stated. Explicitly negated = explicitly absent. Uncertain = contradictory, qualified, or unresolved. Not mentioned = not stated. Blank = not annotated.
A6: Values | B6: Enter a number only when stated. Keep qualitative values in reported_text. For Not mentioned or Explicitly negated, leave numeric_value blank. Do not impute zero.
A7: Supporting quote | B7: Quote exact source wording for stated or uncertain facts. For Not mentioned use NOT STATED, with source_report Not applicable. For negation, quote the negation.
A8: Time and source | B8: Separate current from earlier facts. Use a second row for an earlier measurement, repeat measurement, or conflicting report. Do not overwrite the first observation.
A9: Interventions | B9: Record drug/treatment, dose, route, timing, and given vs planned only if stated. Add separate rows and notes when needed. Never invent a dose or route.
A10: Coverage | B10: Seed fields are a minimum checklist, not an exhaustive schema. Add symptoms, glucose, temperature, onset, history, medications, and repeated observations as needed.
A11: Attention categories | B11: Draft situational-awareness labels, not ESI or clinical triage classes. Prepare now / Preparation can wait / Routine awareness / Cannot assess. Doctor must approve definitions before finalized labels count.
A12: Meaningful change | B12: Use only supplied prior/current reports. No prior information is separate from No change. Quote evidence; allow Uncertain and describe conflicting measurements.
... A24: Claim limit | B24: Results measure agreement with clinician-reviewed simulated examples. They do not establish clinical validity, patient benefit, real-world calibration, or HIPAA compliance.
